Workbook

Sheet Sampling
A1: Experiment ID | B1: Reactor # (If Applicable) | C1: Date Started | D1: Date Sampled | E1: Duration (Days) | F1: Sample Description | G1: NMR | H1: GC | I1: ICP | J1: pH | K1: Conductivity | L1: XRD | M1: Modification
A2: HPHT_097 | C2: 46093 | D2: 46094 | E2: =D2-C2 -> 1 | F2: Liquid and Gas sample | G2: x | H2: x | I2: x | J2: x | K2: x
A3: HPHT_070 | C3: 46034 | D3: 46094 | E3: =D3-C3 -> 60 | F3: Final liquid + gas sample | G3: x | H3: x | I3: x | J3: x | K3: x | M3: x
A4: HPHT_089 | C4: 46094 | D4: 46094 | E4: =D4-C4 -> 0 | F4: Pre-rxn brine check | G4: x | I4: x | J4: x | K4: x
A5: NH4-Teflon | C5: 46094 | D5: 46094 | E5: =D5-C5 -> 0 | F5: NH4 adsorption to teflon | G5: x
A6: NH4-Teflon | C6: 46094 | D6: 46097 | E6: =D6-C6 -> 3 | F6: NH4 adsorption to teflon | G6: x
A7: HPHT_070_Desorption | C7: 46094 | D7: 46094 | E7: =D7-C7 -> 0 | F7: Initial desorption | G7: x
A8: HPHT_101 | C8: 46094 | D8: 46097 | E8: =D8-C8 -> 3 | F8: Reactor 8 background | G8: x | I8: x | J8: x | K8: x
A9: HPHT_102 | C9: 46094 | D9: 46097 | E9: =D9-C9 -> 3 | F9: Reactor 9 background | G9: x | I9: x | J9: x | K9: x
A10: HPHT_095_Desorption | C10: 46094 | D10: 46097 | E10: =D10-C10 -> 3 | F10: Desorption test | G10: x
A11: HPHT_097 | C11: 46093 | D11: 46097 | E11: =D11-C11 -> 4 | F11: CaI experiment day 3 | G11: x | I11: x | J11: x | K11: x
A12: Standard | C12: 46097 | D12: 46097 | E12: =D12-C12 -> 0 | F12: 150uL 1mM NH4Cl | G12: x
A13: HPHT_096 | C13: 46087 | D13: 46097 | E13: =D13-C13 -> 10 | F13: Liquid and gas sample | G13: x | H13: x | I13: x | J13: x | K13: x | L13: x | M13: x
A14: HPHT_079 | C14: 46058 | D14: 46097 | E14: =D14-C14 -> 39 | F14: CaO Gas sample | G14: x | H14: x | I14: x | J14: x | K14: x | L14: x | M14: x
A15: HPHT_097 | C15: 46093 | D15: 46099 | E15: =D15-C15 -> 6 | F15: CaI2 Gas, Liquid, Rock Sample | G15: x | H15: x | I15: x | J15: x | K15: x | L15: x | M15: x
A16: HPHT_087 | C16: 46074 | D16: 46080 | E16: =D16-C16 -> 6 | F16: 0.007mL/min at 220C for 2 days | I16: x
A17: HPHT_070 | C17: 46034 | D17: 46080 | E17: =D17-C17 -> 46 | F17: Final liquid + gas sample | I17: x
A18: HPHT_071-2 | C18: 46062 | D18: 46080 | E18: =D18-C18 -> 18 | F18: Acetate Buffer, contnued 18 days, liquid from gas port | I18: x
A19: HPHT_079 | C19: 46058 | D19: 46080 | E19: =D19-C19 -> 22 | F19: CaO Gas sample
A20: HPHT_071-2 | C20: 46063 | D20: 46083 | E20: =D20-C20 -> 20 | F20: 2 days at 20C, hydrogen generated, dip tube sample high peak | I20: x
A21: HPHT_087 | C21: 46075 | D21: 46083 | E21: =D21-C21 -> 8 | F21: 0.007mL/min at 300C for 2 days | I21: x
A22: HPHT_090 | C22: 46073 | D22: 46083 | E22: =D22-C22 -> 10 | F22: Tamarack continued | I22: x
A23: HPHT_093 | C23: 46081 | D23: 46083 | E23: =D23-C23 -> 2 | F23: Reactor 6 background | I23: x
A24: HPHT_070 | C24: 46034 | D24: 46086 | E24: =D24-C24 -> 52 | F24: Final liquid + gas sample | I24: x
A25: HPHT_071-2 | C25: 46064 | D25: 46086 | E25: =D25-C25 -> 22 | F25: 2 days at 20C, hydrogen generated, final sample | I25: x
A26: HPHT_079 | C26: 46058 | D26: 46086 | E26: =D26-C26 -> 28 | F26: CaO Gas sample | I26: x
A27: HPHT_087 | C27: 46086 | D27: 46086 | E27: =D27-C27 -> 0 | F27: Pre-rxn brine check | I27: x
A28: HPHT_087 | C28: 46076 | D28: 46086 | E28: =D28-C28 -> 10 | F28: 300C @ 4800 PSI | I28: x
A29: HPHT_090 | C29: 46074 | D29: 46086 | E29: =D29-C29 -> 12 | F29: Tamarack continued W:R 5:1 | I29: x
A30: HPHT_095 | C30: 46086 | D30: 46086 | E30: =D30-C30 -> 0 | F30: Pre-rxn brine check | I30: x
A31: HPHT_079 | C31: 46058 | D31: 46092 | E31: =D31-C31 -> 34 | F31: CaO Gas sample | I31: x
... A37: HPHT_095 | C37: 46088 | D37: 46092 | E37: =D37-C37 -> 4 | F37: Tamarack W:R 1:1, low fluid level | I37: x
A38: HPHT_103 | B38: 5 | C38: 46099 | D38: 46099 | E38: =D38-C38 -> 0 | F38: Pre-rxn brine check | G38: x | I38: x | J38: x | K38: x
A39: HPHT_104 | B39: 6 | C39: 46099 | D39: 46099 | E39: =D39-C39 -> 0 | F39: Pre-rxn brine check | G39: x | I39: x | J39: x | K39: x
A40: HPHT_096 | B40: 2 | C40: 46087 | D40: 46097 | E40: =D40-C40 -> 10 | F40: NMR tube 10 from 3/16/26 | G40: x
A41: NMR Standard | C41: 46099 | D41: 46099 | E41: =D41-C41 -> 0 | F41: NH4 Standard NMR | G41: x
A42: HPHT_070_Desorption | C42: 46094 | D42: 46099 | E42: =D42-C42 -> 5 | F42: Desorption test | G42: x
A43: HPHT_089 | B43: 1 | C43: 46097 | D43: 46100 | E43: =D43-C43 -> 3 | F43: Liquid and Gas sample | G43: x | H43: x | J43: x | K43: x | L43: x
A44: HPHT_096 | B44: 2 | C44: 46087 | D44: 46100 | E44: =D44-C44 -> 13 | F44: Liquid and Gas sample | G44: x | H44: x | J44: x | K44: x | M44: x
A45: HPHT_079 | B45: 3 | C45: 46058 | D45: 46100 | E45: =D45-C45 -> 42 | F45: Gas sample | H45: x
...

Sheet NMR Prep
A1: Date Sampled | B1: Experiment ID | C1: Duration (Days) | D1: Sample Description | E1: # | F1: d-DMSO (uL) | G1: 27 mM GdNO3 (uL) | H1: 1mM Maleic Acid (uL) | I1: 8M HCl (uL) | J1: DI (uL) | K1: Sample (uL) | L1: NH4Cl (uL) | M1: NH4Cl Stock Concentration (mM) | N1: Total (uL) | O1: Target (uL) | P1: Difference (uL) | Q1: Number Scans | R1: Spiked NH4 Conc (mM)
A2: =SampleList[[#This Row],[Date Sampled]] -> 46094 | B2: {=IF(ISBLANK(INDEX(SampleList[NMR],ROW()-1)),"Not Requested",INDEX(SampleList[Experiment ID],ROW()-1))} -> HPHT_097 | C2: =SampleList[[#This Row],[Duration (Days)]] -> 1 | D2: =SampleList[[#This Row],[Sample Description]] -> Liquid and Gas sample | F2: 100 | G2: 24 | H2: 50 | I2: 30 | J2: 375 | K2: 68 | N2: =SUM(NMRPrep[[#This Row],[d-DMSO (uL) ]:[ NH4Cl (uL)]]) -> 647 | O2: =647 -> 647 | P2: =NMRPrep[[#This Row],[Total (uL) ]]-NMRPrep[[#This Row],[Target (uL)]] -> 0 | R2: =(NMRPrep[[#This Row],[NH4Cl Stock Concentration (mM)]]*NMRPrep[[#This Row],[ NH4Cl (uL)]])/SUM(NMRPrep[[#This Row],[DI (uL) ]:[ NH4Cl (uL)]]) -> 0
A3: =SampleList[[#This Row],[Date Sampled]] -> 46094 | B3: {=IF(ISBLANK(INDEX(SampleList[NMR],ROW()-1)),"Not Requested",INDEX(SampleList[Experiment ID],ROW()-1))} -> HPHT_070 | C3: =SampleList[[#This Row],[Duration (Days)]] -> 60 | D3: =SampleList[[#This Row],[Sample Description]] -> Final liquid + gas sample | F3: 100 | G3: 24 | H3: 50 | I3: 30 | J3: 375 | K3: 68 | N3: =SUM(NMRPrep[[#This Row],[d-DMSO (uL) ]:[ NH4Cl (uL)]]) -> 647 | O3: =647 -> 647 | P3: =NMRPrep[[#This Row],[Total (uL) ]]-NMRPrep[[#This Row],[Target (uL)]] -> 0 | R3: =(NMRPrep[[#This Row],[NH4Cl Stock Concentration (mM)]]*NMRPrep[[#This Row],[ NH4Cl (uL)]])/SUM(NMRPrep[[#This Row],[DI (uL) ]:[ NH4Cl (uL)]]) -> 0
A4: =SampleList[[#This Row],[Date Sampled]] -> 46094 | B4: {=IF(ISBLANK(INDEX(SampleList[NMR],ROW()-1)),"Not Requested",INDEX(SampleList[Experiment ID],ROW()-1))} -> HPHT_089 | C4: =SampleList[[#This Row],[Duration (Days)]] -> 0 | D4: =SampleList[[#This Row],[Sample Description]] -> Pre-rxn brine check | F4: 100 | G4: 24 | H4: 50 | I4: 30 | J4: 375 | K4: 68 | N4: =SUM(NMRPrep[[#This Row],[d-DMSO (uL) ]:[ NH4Cl (uL)]]) -> 647 | O4: =647 -> 647 | P4: =NMRPrep[[#This Row],[Total (uL) ]]-NMRPrep[[#This Row],[Target (uL)]] -> 0 | R4: =(NMRPrep[[#This Row],[NH4Cl Stock Concentration (mM)]]*NMRPrep[[#This Row],[ NH4Cl (uL)]])/SUM(NMRPrep[[#This Row],[DI (uL) ]:[ NH4Cl (uL)]]) -> 0
A5: =SampleList[[#This Row],[Date Sampled]] -> 46094 | B5: {=IF(ISBLANK(INDEX(SampleList[NMR],ROW()-1)),"Not Requested",INDEX(SampleList[Experiment ID],ROW()-1))} -> NH4-Teflon | C5: =SampleList[[#This Row],[Duration (Days)]] -> 0 | D5: =SampleList[[#This Row],[Sample Description]] -> NH4 adsorption to teflon | F5: 100 | G5: 24 | H5: 50 | I5: 30 | J5: 375 | K5: 68 | N5: =SUM(NMRPrep[[#This Row],[d-DMSO (uL) ]:[ NH4Cl (uL)]]) -> 647 | O5: =647 -> 647 | P5: =NMRPrep[[#This Row],[Total (uL) ]]-NMRPrep[[#This Row],[Target (uL)]] -> 0 | R5: =(NMRPrep[[#This Row],[NH4Cl Stock Concentration (mM)]]*NMRPrep[[#This Row],[ NH4Cl (uL)]])/SUM(NMRPrep[[#This Row],[DI (uL) ]:[ NH4Cl (uL)]]) -> 0
A6: =SampleList[[#This Row],[Date Sampled]] -> 46097 | B6: {=IF(ISBLANK(INDEX(SampleList[NMR],ROW()-1)),"Not Requested",INDEX(SampleList[Experiment ID],ROW()-1))} -> NH4-Teflon | C6: =SampleList[[#This Row],[Duration (Days)]] -> 3 | D6: =SampleList[[#This Row],[Sample Description]] -> NH4 adsorption to teflon | F6: 100 | G6: 24 | H6: 50 | I6: 30 | J6: 375 | K6: 68 | N6: =SUM(NMRPrep[[#This Row],[d-DMSO (uL) ]:[ NH4Cl (uL)]]) -> 647 | O6: =647 -> 647 | P6: =NMRPrep[[#This Row],[Total (uL) ]]-NMRPrep[[#This Row],[Target (uL)]] -> 0 | R6: =(NMRPrep[[#This Row],[NH4Cl Stock Concentration (mM)]]*NMRPrep[[#This Row],[ NH4Cl (uL)]])/SUM(NMRPrep[[#This Row],[DI (uL) ]:[ NH4Cl (uL)]]) -> 0
A7: =SampleList[[#This Row],[Date Sampled]] -> 46094 | B7: {=IF(ISBLANK(INDEX(SampleList[NMR],ROW()-1)),"Not Requested",INDEX(SampleList[Experiment ID],ROW()-1))} -> HPHT_070_Desorption | C7: =SampleList[[#This Row],[Duration (Days)]] -> 0 | D7: =SampleList[[#This Row],[Sample Description]] -> Initial desorption | F7: 100 | G7: 24 | H7: 50 | I7: 30 | J7: 375 | K7: 68 | N7: =SUM(NMRPrep[[#This Row],[d-DMSO (uL) ]:[ NH4Cl (uL)]]) -> 647 | O7: =647 -> 647 | P7: =NMRPrep[[#This Row],[Total (uL) ]]-NMRPrep[[#This Row],[Target (uL)]] -> 0 | R7: =(NMRPrep[[#This Row],[NH4Cl Stock Concentration (mM)]]*NMRPrep[[#This Row],[ NH4Cl (uL)]])/SUM(NMRPrep[[#This Row],[DI (uL) ]:[ NH4Cl (uL)]]) -> 0
A8: =SampleList[[#This Row],[Date Sampled]] -> 46097 | B8: {=IF(ISBLANK(INDEX(SampleList[NMR],ROW()-1)),"Not Requested",INDEX(SampleList[Experiment ID],ROW()-1))} -> HPHT_101 | C8: =SampleList[[#This Row],[Duration (Days)]] -> 3 | D8: =SampleList[[#This Row],[Sample Description]] -> Reactor 8 background | F8: 100 | G8: 24 | H8: 50 | I8: 30 | J8: 375 | K8: 68 | N8: =SUM(NMRPrep[[#This Row],[d-DMSO (uL) ]:[ NH4Cl (uL)]]) -> 647 | O8: =647 -> 647 | P8: =NMRPrep[[#This Row],[Total (uL) ]]-NMRPrep[[#This Row],[Target (uL)]] -> 0 | R8: =(NMRPrep[[#This Row],[NH4Cl Stock Concentration (mM)]]*NMRPrep[[#This Row],[ NH4Cl (uL)]])/SUM(NMRPrep[[#This Row],[DI (uL) ]:[ NH4Cl (uL)]]) -> 0
A9: =SampleList[[#This Row],[Date Sampled]] -> 46097 | B9: {=IF(ISBLANK(INDEX(SampleList[NMR],ROW()-1)),"Not Requested",INDEX(SampleList[Experiment ID],ROW()-1))} -> HPHT_102 | C9: =SampleList[[#This Row],[Duration (Days)]] -> 3 | D9: =SampleList[[#This Row],[Sample Description]] -> Reactor 9 background | F9: 100 | G9: 24 | H9: 50 | I9: 30 | J9: 375 | K9: 68 | N9: =SUM(NMRPrep[[#This Row],[d-DMSO (uL) ]:[ NH4Cl (uL)]]) -> 647 | O9: =647 -> 647 | P9: =NMRPrep[[#This Row],[Total (uL) ]]-NMRPrep[[#This Row],[Target (uL)]] -> 0 | R9: =(NMRPrep[[#This Row],[NH4Cl Stock Concentration (mM)]]*NMRPrep[[#This Row],[ NH4Cl (uL)]])/SUM(NMRPrep[[#This Row],[DI (uL) ]:[ NH4Cl (uL)]]) -> 0
A10: =SampleList[[#This Row],[Date Sampled]] -> 46097 | B10: {=IF(ISBLANK(INDEX(SampleList[NMR],ROW()-1)),"Not Requested",INDEX(SampleList[Experiment ID],ROW()-1))} -> HPHT_095_Desorption | C10: =SampleList[[#This Row],[Duration (Days)]] -> 3 | D10: =SampleList[[#This Row],[Sample Description]] -> Desorption test | F10: 100 | G10: 24 | H10: 50 | I10: 30 | J10: 375 | K10: 68 | N10: =SUM(NMRPrep[[#This Row],[d-DMSO (uL) ]:[ NH4Cl (uL)]]) -> 647 | O10: =647 -> 647 | P10: =NMRPrep[[#This Row],[Total (uL) ]]-NMRPrep[[#This Row],[Target (uL)]] -> 0 | R10: =(NMRPrep[[#This Row],[NH4Cl Stock Concentration (mM)]]*NMRPrep[[#This Row],[ NH4Cl (uL)]])/SUM(NMRPrep[[#This Row],[DI (uL) ]:[ NH4Cl (uL)]]) -> 0
A11: =SampleList[[#This Row],[Date Sampled]] -> 46097 | B11: {=IF(ISBLANK(INDEX(SampleList[NMR],ROW()-1)),"Not Requested",INDEX(SampleList[Experiment ID],ROW()-1))} -> HPHT_097 | C11: =SampleList[[#This Row],[Duration (Days)]] -> 4 | D11: =SampleList[[#This Row],[Sample Description]] -> CaI experiment day 3 | F11: 100 | G11: 24 | H11: 50 | I11: 30 | J11: 375 | K11: 68 | N11: =SUM(NMRPrep[[#This Row],[d-DMSO (uL) ]:[ NH4Cl (uL)]]) -> 647 | O11: =647 -> 647 | P11: =NMRPrep[[#This Row],[Total (uL) ]]-NMRPrep[[#This Row],[Target (uL)]] -> 0 | R11: =(NMRPrep[[#This Row],[NH4Cl Stock Concentration (mM)]]*NMRPrep[[#This Row],[ NH4Cl (uL)]])/SUM(NMRPrep[[#This Row],[DI (uL) ]:[ NH4Cl (uL)]]) -> 0
A12: =SampleList[[#This Row],[Date Sampled]] -> 46097 | B12: {=IF(ISBLANK(INDEX(SampleList[NMR],ROW()-1)),"Not Requested",INDEX(SampleList[Experiment ID],ROW()-1))} -> Standard | C12: =SampleList[[#This Row],[Duration (Days)]] -> 0 | D12: =SampleList[[#This Row],[Sample Description]] -> 150uL 1mM NH4Cl | F12: 100 | G12: 24 | H12: 50 | I12: 30 | J12: 293 | K12: 0 | L12: 150 | N12: =SUM(NMRPrep[[#This Row],[d-DMSO (uL) ]:[ NH4Cl (uL)]]) -> 647 | O12: =647 -> 647 | P12: =NMRPrep[[#This Row],[Total (uL) ]]-NMRPrep[[#This Row],[Target (uL)]] -> 0 | R12: =(NMRPrep[[#This Row],[NH4Cl Stock Concentration (mM)]]*NMRPrep[[#This Row],[ NH4Cl (uL)]])/SUM(NMRPrep[[#This Row],[DI (uL) ]:[ NH4Cl (uL)]]) -> 0
A13: =SampleList[[#This Row],[Date Sampled]] -> 46097 | B13: {=IF(ISBLANK(INDEX(SampleList[NMR],ROW()-1)),"Not Requested",INDEX(SampleList[Experiment ID],ROW()-1))} -> HPHT_096 | C13: =SampleList[[#This Row],[Duration (Days)]] -> 10 | D13: =SampleList[[#This Row],[Sample Description]] -> Liquid and gas sample | F13: 100 | G13: 24 | H13: 50 | I13: 30 | J13: 375 | K13: 68 | N13: =SUM(NMRPrep[[#This Row],[d-DMSO (uL) ]:[ NH4Cl (uL)]]) -> 647 | O13: =647 -> 647 | P13: =NMRPrep[[#This Row],[Total (uL) ]]-NMRPrep[[#This Row],[Target (uL)]] -> 0 | R13: =(NMRPrep[[#This Row],[NH4Cl Stock Concentration (mM)]]*NMRPrep[[#This Row],[ NH4Cl (uL)]])/SUM(NMRPrep[[#This Row],[DI (uL) ]:[ NH4Cl (uL)]]) -> 0
A14: =SampleList[[#This Row],[Date Sampled]] -> 46097 | B14: {=IF(ISBLANK(INDEX(SampleList[NMR],ROW()-1)),"Not Requested",INDEX(SampleList[Experiment ID],ROW()-1))} -> HPHT_079 | C14: =SampleList[[#This Row],[Duration (Days)]] -> 39 | D14: =SampleList[[#This Row],[Sample Description]] -> CaO Gas sample | F14: 100 | G14: 24 | H14: 50 | I14: 30 | J14: 375 | K14: 68 | N14: =SUM(NMRPrep[[#This Row],[d-DMSO (uL) ]:[ NH4Cl (uL)]]) -> 647 | O14: =647 -> 647 | P14: =NMRPrep[[#This Row],[Total (uL) ]]-NMRPrep[[#This Row],[Target (uL)]] -> 0 | R14: =(NMRPrep[[#This Row],[NH4Cl Stock Concentration (mM)]]*NMRPrep[[#This Row],[ NH4Cl (uL)]])/SUM(NMRPrep[[#This Row],[DI (uL) ]:[ NH4Cl (uL)]]) -> 0
A15: =SampleList[[#This Row],[Date Sampled]] -> 46099 | B15: {=IF(ISBLANK(INDEX(SampleList[NMR],ROW()-1)),"Not Requested",INDEX(SampleList[Experiment ID],ROW()-1))} -> HPHT_097 | C15: =SampleList[[#This Row],[Duration (Days)]] -> 6 | D15: =SampleList[[#This Row],[Sample Description]] -> CaI2 Gas, Liquid, Rock Sample | F15: 100 | G15: 24 | H15: 50 | I15: 30 | J15: 375 | K15: 68 | N15: =SUM(NMRPrep[[#This Row],[d-DMSO (uL) ]:[ NH4Cl (uL)]]) -> 647 | O15: =647 -> 647 | P15: =NMRPrep[[#This Row],[Total (uL) ]]-NMRPrep[[#This Row],[Target (uL)]] -> 0 | R15: =(NMRPrep[[#This Row],[NH4Cl Stock Concentration (mM)]]*NMRPrep[[#This Row],[ NH4Cl (uL)]])/SUM(NMRPrep[[#This Row],[DI (uL) ]:[ NH4Cl (uL)]]) -> 0
A16: =SampleList[[#This Row],[Date Sampled]] -> 46080 | B16: {=IF(ISBLANK(INDEX(SampleList[NMR],ROW()-1)),"Not Requested",INDEX(SampleList[Experiment ID],ROW()-1))} -> Not Requested | C16: =SampleList[[#This Row],[Duration (Days)]] -> 6 | D16: =SampleList[[#This Row],[Sample Description]] -> 0.007mL/min at 220C for 2 days | F16: 100 | G16: 24 | H16: 50 | I16: 30 | J16: 375 | K16: 68 | N16: =SUM(NMRPrep[[#This Row],[d-DMSO (uL) ]:[ NH4Cl (uL)]]) -> 647 | O16: =647 -> 647 | P16: =NMRPrep[[#This Row],[Total (uL) ]]-NMRPrep[[#This Row],[Target (uL)]] -> 0 | R16: =(NMRPrep[[#This Row],[NH4Cl Stock Concentration (mM)]]*NMRPrep[[#This Row],[ NH4Cl (uL)]])/SUM(NMRPrep[[#This Row],[DI (uL) ]:[ NH4Cl (uL)]]) -> 0
A17: =SampleList[[#This Row],[Date Sampled]] -> 46080 | B17: {=IF(ISBLANK(INDEX(SampleList[NMR],ROW()-1)),"Not Requested",INDEX(SampleList[Experiment ID],ROW()-1))} -> Not Requested | C17: =SampleList[[#This Row],[Duration (Days)]] -> 46 | D17: =SampleList[[#This Row],[Sample Description]] -> Final liquid + gas sample | F17: 100 | G17: 24 | H17: 50 | I17: 30 | J17: 375 | K17: 68 | N17: =SUM(NMRPrep[[#This Row],[d-DMSO (uL) ]:[ NH4Cl (uL)]]) -> 647 | O17: =647 -> 647 | P17: =NMRPrep[[#This Row],[Total (uL) ]]-NMRPrep[[#This Row],[Target (uL)]] -> 0 | R17: =(NMRPrep[[#This Row],[NH4Cl Stock Concentration (mM)]]*NMRPrep[[#This Row],[ NH4Cl (uL)]])/SUM(NMRPrep[[#This Row],[DI (uL) ]:[ NH4Cl (uL)]]) -> 0
A18: =SampleList[[#This Row],[Date Sampled]] -> 46080 | B18: {=IF(ISBLANK(INDEX(SampleList[NMR],ROW()-1)),"Not Requested",INDEX(SampleList[Experiment ID],ROW()-1))} -> Not Requested | C18: =SampleList[[#This Row],[Duration (Days)]] -> 18 | D18: =SampleList[[#This Row],[Sample Description]] -> Acetate Buffer, contnued 18 days, liquid from gas port | F18: 100 | G18: 24 | H18: 50 | I18: 30 | J18: 375 | K18: 68 | N18: =SUM(NMRPrep[[#This Row],[d-DMSO (uL) ]:[ NH4Cl (uL)]]) -> 647 | O18: =647 -> 647 | P18: =NMRPrep[[#This Row],[Total (uL) ]]-NMRPrep[[#This Row],[Target (uL)]] -> 0 | R18: =(NMRPrep[[#This Row],[NH4Cl Stock Concentration (mM)]]*NMRPrep[[#This Row],[ NH4Cl (uL)]])/SUM(NMRPrep[[#This Row],[DI (uL) ]:[ NH4Cl (uL)]]) -> 0
A19: =SampleList[[#This Row],[Date Sampled]] -> 46080 | B19: {=IF(ISBLANK(INDEX(SampleList[NMR],ROW()-1)),"Not Requested",INDEX(SampleList[Experiment ID],ROW()-1))} -> Not Requested | C19: =SampleList[[#This Row],[Duration (Days)]] -> 22 | D19: =SampleList[[#This Row],[Sample Description]] -> CaO Gas sample | F19: 100 | G19: 24 | H19: 50 | I19: 30 | J19: 375 | K19: 68 | N19: =SUM(NMRPrep[[#This Row],[d-DMSO (uL) ]:[ NH4Cl (uL)]]) -> 647 | O19: =647 -> 647 | P19: =NMRPrep[[#This Row],[Total (uL) ]]-NMRPrep[[#This Row],[Target (uL)]] -> 0 | R19: =(NMRPrep[[#This Row],[NH4Cl Stock Concentration (mM)]]*NMRPrep[[#This Row],[ NH4Cl (uL)]])/SUM(NMRPrep[[#This Row],[DI (uL) ]:[ NH4Cl (uL)]]) -> 0
A20: =SampleList[[#This Row],[Date Sampled]] -> 46083 | B20: {=IF(ISBLANK(INDEX(SampleList[NMR],ROW()-1)),"Not Requested",INDEX(SampleList[Experiment ID],ROW()-1))} -> Not Requested | C20: =SampleList[[#This Row],[Duration (Days)]] -> 20 | D20: =SampleList[[#This Row],[Sample Description]] -> 2 days at 20C, hydrogen generated, dip tube sample high peak | F20: 100 | G20: 24 | H20: 50 | I20: 30 | J20: 375 | K20: 68 | N20: =SUM(NMRPrep[[#This Row],[d-DMSO (uL) ]:[ NH4Cl (uL)]]) -> 647 | O20: =647 -> 647 | P20: =NMRPrep[[#This Row],[Total (uL) ]]-NMRPrep[[#This Row],[Target (uL)]] -> 0 | R20: =(NMRPrep[[#This Row],[NH4Cl Stock Concentration (mM)]]*NMRPrep[[#This Row],[ NH4Cl (uL)]])/SUM(NMRPrep[[#This Row],[DI (uL) ]:[ NH4Cl (uL)]]) -> 0
A21: =SampleList[[#This Row],[Date Sampled]] -> 46083 | B21: {=IF(ISBLANK(INDEX(SampleList[NMR],ROW()-1)),"Not Requested",INDEX(SampleList[Experiment ID],ROW()-1))} -> Not Requested | C21: =SampleList[[#This Row],[Duration (Days)]] -> 8 | D21: =SampleList[[#This Row],[Sample Description]] -> 0.007mL/min at 300C for 2 days | F21: 100 | G21: 24 | H21: 50 | I21: 30 | J21: 375 | K21: 68 | N21: =SUM(NMRPrep[[#This Row],[d-DMSO (uL) ]:[ NH4Cl (uL)]]) -> 647 | O21: =647 -> 647 | P21: =NMRPrep[[#This Row],[Total (uL) ]]-NMRPrep[[#This Row],[Target (uL)]] -> 0 | R21: =(NMRPrep[[#This Row],[NH4Cl Stock Concentration (mM)]]*NMRPrep[[#This Row],[ NH4Cl (uL)]])/SUM(NMRPrep[[#This Row],[DI (uL) ]:[ NH4Cl (uL)]]) -> 0
A22: =SampleList[[#This Row],[Date Sampled]] -> 46083 | B22: {=IF(ISBLANK(INDEX(SampleList[NMR],ROW()-1)),"Not Requested",INDEX(SampleList[Experiment ID],ROW()-1))} -> Not Requested | C22: =SampleList[[#This Row],[Duration (Days)]] -> 10 | D22: =SampleList[[#This Row],[Sample Description]] -> Tamarack continued | F22: 100 | G22: 24 | H22: 50 | I22: 30 | J22: 375 | K22: 68 | N22: =SUM(NMRPrep[[#This Row],[d-DMSO (uL) ]:[ NH4Cl (uL)]]) -> 647 | O22: =647 -> 647 | P22: =NMRPrep[[#This Row],[Total (uL) ]]-NMRPrep[[#This Row],[Target (uL)]] -> 0 | R22: =(NMRPrep[[#This Row],[NH4Cl Stock Concentration (mM)]]*NMRPrep[[#This Row],[ NH4Cl (uL)]])/SUM(NMRPrep[[#This Row],[DI (uL) ]:[ NH4Cl (uL)]]) -> 0
A23: =SampleList[[#This Row],[Date Sampled]] -> 46083 | B23: {=IF(ISBLANK(INDEX(SampleList[NMR],ROW()-1)),"Not Requested",INDEX(SampleList[Experiment ID],ROW()-1))} -> Not Requested | C23: =SampleList[[#This Row],[Duration (Days)]] -> 2 | D23: =SampleList[[#This Row],[Sample Description]] -> Reactor 6 background | F23: 100 | G23: 24 | H23: 50 | I23: 30 | J23: 375 | K23: 68 | N23: =SUM(NMRPrep[[#This Row],[d-DMSO (uL) ]:[ NH4Cl (uL)]]) -> 647 | O23: =647 -> 647 | P23: =NMRPrep[[#This Row],[Total (uL) ]]-NMRPrep[[#This Row],[Target (uL)]] -> 0 | R23: =(NMRPrep[[#This Row],[NH4Cl Stock Concentration (mM)]]*NMRPrep[[#This Row],[ NH4Cl (uL)]])/SUM(NMRPrep[[#This Row],[DI (uL) ]:[ NH4Cl (uL)]]) -> 0
A24: =SampleList[[#This Row],[Date Sampled]] -> 46086 | B24: {=IF(ISBLANK(INDEX(SampleList[NMR],ROW()-1)),"Not Requested",INDEX(SampleList[Experiment ID],ROW()-1))} -> Not Requested | C24: =SampleList[[#This Row],[Duration (Days)]] -> 52 | D24: =SampleList[[#This Row],[Sample Description]] -> Final liquid + gas sample | F24: 100 | G24: 24 | H24: 50 | I24: 30 | J24: 375 | K24: 68 | N24: =SUM(NMRPrep[[#This Row],[d-DMSO (uL) ]:[ NH4Cl (uL)]]) -> 647 | O24: =647 -> 647 | P24: =NMRPrep[[#This Row],[Total (uL) ]]-NMRPrep[[#This Row],[Target (uL)]] -> 0 | R24: =(NMRPrep[[#This Row],[NH4Cl Stock Concentration (mM)]]*NMRPrep[[#This Row],[ NH4Cl (uL)]])/SUM(NMRPrep[[#This Row],[DI (uL) ]:[ NH4Cl (uL)]]) -> 0
... A40: =SampleList[[#This Row],[Date Sampled]] -> 46097 | B40: {=IF(ISBLANK(INDEX(SampleList[NMR],ROW()-1)),"Not Requested",INDEX(SampleList[Experiment ID],ROW()-1))} -> HPHT_096 | C40: =SampleList[[#This Row],[Duration (Days)]] -> 10 | D40: =SampleList[[#This Row],[Sample Description]] -> NMR tube 10 from 3/16/26 | F40: 100 | G40: 24 | H40: 50 | I40: 30 | J40: 375 | K40: 68 | N40: =SUM(NMRPrep[[#This Row],[d-DMSO (uL) ]:[ NH4Cl (uL)]]) -> 647 | O40: =647 -> 647 | P40: =NMRPrep[[#This Row],[Total (uL) ]]-NMRPrep[[#This Row],[Target (uL)]] -> 0 | R40: =(NMRPrep[[#This Row],[NH4Cl Stock Concentration (mM)]]*NMRPrep[[#This Row],[ NH4Cl (uL)]])/SUM(NMRPrep[[#This Row],[DI (uL) ]:[ NH4Cl (uL)]]) -> 0
A41: =SampleList[[#This Row],[Date Sampled]] -> 46099 | B41: {=IF(ISBLANK(INDEX(SampleList[NMR],ROW()-1)),"Not Requested",INDEX(SampleList[Experiment ID],ROW()-1))} -> NMR Standard | C41: =SampleList[[#This Row],[Duration (Days)]] -> 0 | D41: =SampleList[[#This Row],[Sample Description]] -> NH4 Standard NMR | F41: 100 | G41: 24 | H41: 50 | I41: 30 | J41: 293 | K41: 0 | L41: 150 | N41: =SUM(NMRPrep[[#This Row],[d-DMSO (uL) ]:[ NH4Cl (uL)]]) -> 647 | O41: =647 -> 647 | P41: =NMRPrep[[#This Row],[Total (uL) ]]-NMRPrep[[#This Row],[Target (uL)]] -> 0 | R41: =(NMRPrep[[#This Row],[NH4Cl Stock Concentration (mM)]]*NMRPrep[[#This Row],[ NH4Cl (uL)]])/SUM(NMRPrep[[#This Row],[DI (uL) ]:[ NH4Cl (uL)]]) -> 0
A42: =SampleList[[#This Row],[Date Sampled]] -> 46099 | B42: {=IF(ISBLANK(INDEX(SampleList[NMR],ROW()-1)),"Not Requested",INDEX(SampleList[Experiment ID],ROW()-1))} -> HPHT_070_Desorption | C42: =SampleList[[#This Row],[Duration (Days)]] -> 5 | D42: =SampleList[[#This Row],[Sample Description]] -> Desorption test | F42: 100 | G42: 24 | H42: 50 | I42: 30 | J42: 375 | K42: 68 | N42: =SUM(NMRPrep[[#This Row],[d-DMSO (uL) ]:[ NH4Cl (uL)]]) -> 647 | O42: =647 -> 647 | P42: =NMRPrep[[#This Row],[Total (uL) ]]-NMRPrep[[#This Row],[Target (uL)]] -> 0 | R42: =(NMRPrep[[#This Row],[NH4Cl Stock Concentration (mM)]]*NMRPrep[[#This Row],[ NH4Cl (uL)]])/SUM(NMRPrep[[#This Row],[DI (uL) ]:[ NH4Cl (uL)]]) -> 0
A43: =SampleList[[#This Row],[Date Sampled]] -> 46100 | B43: {=IF(ISBLANK(INDEX(SampleList[NMR],ROW()-1)),"Not Requested",INDEX(SampleList[Experiment ID],ROW()-1))} -> HPHT_089 | C43: =SampleList[[#This Row],[Duration (Days)]] -> 3 | D43: =SampleList[[#This Row],[Sample Description]] -> Liquid and Gas sample | E43: 1 | F43: 100 | G43: 24 | H43: 50 | I43: 30 | J43: 375 | K43: 68 | N43: =SUM(NMRPrep[[#This Row],[d-DMSO (uL) ]:[ NH4Cl (uL)]]) -> 647 | O43: =647 -> 647 | P43: =NMRPrep[[#This Row],[Total (uL) ]]-NMRPrep[[#This Row],[Target (uL)]] -> 0 | R43: =(NMRPrep[[#This Row],[NH4Cl Stock Concentration (mM)]]*NMRPrep[[#This Row],[ NH4Cl (uL)]])/SUM(NMRPrep[[#This Row],[DI (uL) ]:[ NH4Cl (uL)]]) -> 0
A44: =SampleList[[#This Row],[Date Sampled]] -> 46100 | B44: {=IF(ISBLANK(INDEX(SampleList[NMR],ROW()-1)),"Not Requested",INDEX(SampleList[Experiment ID],ROW()-1))} -> HPHT_096 | C44: =SampleList[[#This Row],[Duration (Days)]] -> 13 | D44: =SampleList[[#This Row],[Sample Description]] -> Liquid and Gas sample | E44: 2 | F44: 100 | G44: 24 | H44: 50 | I44: 30 | J44: 375 | K44: 68 | N44: =SUM(NMRPrep[[#This Row],[d-DMSO (uL) ]:[ NH4Cl (uL)]]) -> 647 | O44: =647 -> 647 | P44: =NMRPrep[[#This Row],[Total (uL) ]]-NMRPrep[[#This Row],[Target (uL)]] -> 0 | R44: =(NMRPrep[[#This Row],[NH4Cl Stock Concentration (mM)]]*NMRPrep[[#This Row],[ NH4Cl (uL)]])/SUM(NMRPrep[[#This Row],[DI (uL) ]:[ NH4Cl (uL)]]) -> 0
A45: =SampleList[[#This Row],[Date Sampled]] -> 46100 | B45: {=IF(ISBLANK(INDEX(SampleList[NMR],ROW()-1)),"Not Requested",INDEX(SampleList[Experiment ID],ROW()-1))} -> Not Requested | C45: =SampleList[[#This Row],[Duration (Days)]] -> 42 | D45: =SampleList[[#This Row],[Sample Description]] -> Gas sample | N45: =SUM(NMRPrep[[#This Row],[d-DMSO (uL) ]:[ NH4Cl (uL)]]) -> 0 | O45: =647 -> 647 | P45: =NMRPrep[[#This Row],[Total (uL) ]]-NMRPrep[[#This Row],[Target (uL)]] -> -647 | R45: =(NMRPrep[[#This Row],[NH4Cl Stock Concentration (mM)]]*NMRPrep[[#This Row],[ NH4Cl (uL)]])/SUM(NMRPrep[[#This Row],[DI (uL) ]:[ NH4Cl (uL)]]) -> #DIV/0!
A46: =SampleList[[#This Row],[Date Sampled]] -> 46101 | B46: {=IF(ISBLANK(INDEX(SampleList[NMR],ROW()-1)),"Not Requested",INDEX(SampleList[Experiment ID],ROW()-1))} -> HPHT_097 | C46: =SampleList[[#This Row],[Duration (Days)]] -> 8 | D46: =SampleList[[#This Row],[Sample Description]] -> Liquid sample | E46: 3 | F46: 100 | G46: 24 | H46: 50 | I46: 30 | J46: 375 | K46: 68 | N46: =SUM(NMRPrep[[#This Row],[d-DMSO (uL) ]:[ NH4Cl (uL)]]) -> 647 | O46: =647 -> 647 | P46: =NMRPrep[[#This Row],[Total (uL) ]]-NMRPrep[[#This Row],[Target (uL)]] -> 0 | R46: =(NMRPrep[[#This Row],[NH4Cl Stock Concentration (mM)]]*NMRPrep[[#This Row],[ NH4Cl (uL)]])/SUM(NMRPrep[[#This Row],[DI (uL) ]:[ NH4Cl (uL)]]) -> 0
A47: =SampleList[[#This Row],[Date Sampled]] -> 46101 | B47: {=IF(ISBLANK(INDEX(SampleList[NMR],ROW()-1)),"Not Requested",INDEX(SampleList[Experiment ID],ROW()-1))} -> HPHT_105 | C47: =SampleList[[#This Row],[Duration (Days)]] -> 3 | D47: =SampleList[[#This Row],[Sample Description]] -> Liquid and Gas sample | E47: 4 | F47: 100 | G47: 24 | H47: 50 | I47: 30 | J47: 375 | K47: 68 | N47: =SUM(NMRPrep[[#This Row],[d-DMSO (uL) ]:[ NH4Cl (uL)]]) -> 647 | O47: =647 -> 647 | P47: =NMRPrep[[#This Row],[Total (uL) ]]-NMRPrep[[#This Row],[Target (uL)]] -> 0 | R47: =(NMRPrep[[#This Row],[NH4Cl Stock Concentration (mM)]]*NMRPrep[[#This Row],[ NH4Cl (uL)]])/SUM(NMRPrep[[#This Row],[DI (uL) ]:[ NH4Cl (uL)]]) -> 0
A48: =SampleList[[#This Row],[Date Sampled]] -> 46101 | B48: {=IF(ISBLANK(INDEX(SampleList[NMR],ROW()-1)),"Not Requested",INDEX(SampleList[Experiment ID],ROW()-1))} -> 150uL NMR Standard | C48: =SampleList[[#This Row],[Duration (Days)]] -> 0 | D48: =SampleList[[#This Row],[Sample Description]] -> 150uL 1mM NH4Cl | E48: 5 | F48: 100 | G48: 24 | H48: 50 | I48: 30 | J48: 293 | K48: 0 | L48: 150 | N48: =SUM(NMRPrep[[#This Row],[d-DMSO (uL) ]:[ NH4Cl (uL)]]) -> 647 | O48: =647 -> 647 | P48: =NMRPrep[[#This Row],[Total (uL) ]]-NMRPrep[[#This Row],[Target (uL)]] -> 0 | R48: =(NMRPrep[[#This Row],[NH4Cl Stock Concentration (mM)]]*NMRPrep[[#This Row],[ NH4Cl (uL)]])/SUM(NMRPrep[[#This Row],[DI (uL) ]:[ NH4Cl (uL)]]) -> 0
A49: =SampleList[[#This Row],[Date Sampled]] -> 46104 | B49: {=IF(ISBLANK(INDEX(SampleList[NMR],ROW()-1)),"Not Requested",INDEX(SampleList[Experiment ID],ROW()-1))} -> HPHT_096 | C49: =SampleList[[#This Row],[Duration (Days)]] -> 17 | D49: =SampleList[[#This Row],[Sample Description]] -> Liquid and gas sample, +450mg Pd | N49: =SUM(NMRPrep[[#This Row],[d-DMSO (uL) ]:[ NH4Cl (uL)]]) -> 0 | O49: =647 -> 647 | P49: =NMRPrep[[#This Row],[Total (uL) ]]-NMRPrep[[#This Row],[Target (uL)]] -> -647 | R49: =(NMRPrep[[#This Row],[NH4Cl Stock Concentration (mM)]]*NMRPrep[[#This Row],[ NH4Cl (uL)]])/SUM(NMRPrep[[#This Row],[DI (uL) ]:[ NH4Cl (uL)]]) -> #DIV/0!
A50: =SampleList[[#This Row],[Date Sampled]] -> 46104 | B50: {=IF(ISBLANK(INDEX(SampleList[NMR],ROW()-1)),"Not Requested",INDEX(SampleList[Experiment ID],ROW()-1))} -> HPHT_089 | C50: =SampleList[[#This Row],[Duration (Days)]] -> 7 | D50: =SampleList[[#This Row],[Sample Description]] -> Liquid and gas sample, pH adjust | N50: =SUM(NMRPrep[[#This Row],[d-DMSO (uL) ]:[ NH4Cl (uL)]]) -> 0 | O50: =647 -> 647 | P50: =NMRPrep[[#This Row],[Total (uL) ]]-NMRPrep[[#This Row],[Target (uL)]] -> -647 | R50: =(NMRPrep[[#This Row],[NH4Cl Stock Concentration (mM)]]*NMRPrep[[#This Row],[ NH4Cl (uL)]])/SUM(NMRPrep[[#This Row],[DI (uL) ]:[ NH4Cl (uL)]]) -> #DIV/0!
A51: =SampleList[[#This Row],[Date Sampled]] -> 46104 | B51: {=IF(ISBLANK(INDEX(SampleList[NMR],ROW()-1)),"Not Requested",INDEX(SampleList[Experiment ID],ROW()-1))} -> Not Requested | C51: =SampleList[[#This Row],[Duration (Days)]] -> 46 | D51: =SampleList[[#This Row],[Sample Description]] -> Gas sample only | N51: =SUM(NMRPrep[[#This Row],[d-DMSO (uL) ]:[ NH4Cl (uL)]]) -> 0 | O51: =647 -> 647 | P51: =NMRPrep[[#This Row],[Total (uL) ]]-NMRPrep[[#This Row],[Target (uL)]] -> -647 | R51: =(NMRPrep[[#This Row],[NH4Cl Stock Concentration (mM)]]*NMRPrep[[#This Row],[ NH4Cl (uL)]])/SUM(NMRPrep[[#This Row],[DI (uL) ]:[ NH4Cl (uL)]]) -> #DIV/0!
A52: =SampleList[[#This Row],[Date Sampled]] -> 46104 | B52: {=IF(ISBLANK(INDEX(SampleList[NMR],ROW()-1)),"Not Requested",INDEX(SampleList[Experiment ID],ROW()-1))} -> HPHT_097 | C52: =SampleList[[#This Row],[Duration (Days)]] -> 11 | D52: =SampleList[[#This Row],[Sample Description]] -> Liquid and gas sample, pH adjust | N52: =SUM(NMRPrep[[#This Row],[d-DMSO (uL) ]:[ NH4Cl (uL)]]) -> 0 | O52: =647 -> 647 | P52: =NMRPrep[[#This Row],[Total (uL) ]]-NMRPrep[[#This Row],[Target (uL)]] -> -647 | R52: =(NMRPrep[[#This Row],[NH4Cl Stock Concentration (mM)]]*NMRPrep[[#This Row],[ NH4Cl (uL)]])/SUM(NMRPrep[[#This Row],[DI (uL) ]:[ NH4Cl (uL)]]) -> #DIV/0!
A53: =SampleList[[#This Row],[Date Sampled]] -> 46104 | B53: {=IF(ISBLANK(INDEX(SampleList[NMR],ROW()-1)),"Not Requested",INDEX(SampleList[Experiment ID],ROW()-1))} -> HPHT_103 | C53: =SampleList[[#This Row],[Duration (Days)]] -> 3 | D53: =SampleList[[#This Row],[Sample Description]] -> Liquid sample only | N53: =SUM(NMRPrep[[#This Row],[d-DMSO (uL) ]:[ NH4Cl (uL)]]) -> 0 | O53: =647 -> 647 | P53: =NMRPrep[[#This Row],[Total (uL) ]]-NMRPrep[[#This Row],[Target (uL)]] -> -647 | R53: =(NMRPrep[[#This Row],[NH4Cl Stock Concentration (mM)]]*NMRPrep[[#This Row],[ NH4Cl (uL)]])/SUM(NMRPrep[[#This Row],[DI (uL) ]:[ NH4Cl (uL)]]) -> #DIV/0!
A54: =SampleList[[#This Row],[Date Sampled]] -> 46104 | B54: {=IF(ISBLANK(INDEX(SampleList[NMR],ROW()-1)),"Not Requested",INDEX(SampleList[Experiment ID],ROW()-1))} -> HPHT_104 | C54: =SampleList[[#This Row],[Duration (Days)]] -> 3 | D54: =SampleList[[#This Row],[Sample Description]] -> Liquid sample only | N54: =SUM(NMRPrep[[#This Row],[d-DMSO (uL) ]:[ NH4Cl (uL)]]) -> 0 | O54: =647 -> 647 | P54: =NMRPrep[[#This Row],[Total (uL) ]]-NMRPrep[[#This Row],[Target (uL)]] -> -647 | R54: =(NMRPrep[[#This Row],[NH4Cl Stock Concentration (mM)]]*NMRPrep[[#This Row],[ NH4Cl (uL)]])/SUM(NMRPrep[[#This Row],[DI (uL) ]:[ NH4Cl (uL)]]) -> #DIV/0!
A55: =SampleList[[#This Row],[Date Sampled]] -> 46104 | B55: {=IF(ISBLANK(INDEX(SampleList[NMR],ROW()-1)),"Not Requested",INDEX(SampleList[Experiment ID],ROW()-1))} -> HPHT_107 | C55: =SampleList[[#This Row],[Duration (Days)]] -> 3 | D55: =SampleList[[#This Row],[Sample Description]] -> Liquid and gas sample | N55: =SUM(NMRPrep[[#This Row],[d-DMSO (uL) ]:[ NH4Cl (uL)]]) -> 0 | O55: =647 -> 647 | P55: =NMRPrep[[#This Row],[Total (uL) ]]-NMRPrep[[#This Row],[Target (uL)]] -> -647 | R55: =(NMRPrep[[#This Row],[NH4Cl Stock Concentration (mM)]]*NMRPrep[[#This Row],[ NH4Cl (uL)]])/SUM(NMRPrep[[#This Row],[DI (uL) ]:[ NH4Cl (uL)]]) -> #DIV/0!
...

Sheet NMR Results
A1: Date Sampled | B1: Experiment ID | C1: Duration (Days) | D1: # | E1: Date Run | F1: NH4 Peak Area | G1: Ammonium Concentration (mM) | H1: IS Concentration (mM) | I1: IS Protons | J1: NH4 Protons | K1: IS Area
A2: =Sampling!D2 -> 46094 | B2: {=IF(ISBLANK(INDEX(SampleList[NMR],ROW()-1)),"Not Requested",INDEX(SampleList[Experiment ID],ROW()-1))} -> HPHT_097 | C2: =SampleList[[#This Row],[Duration (Days)]] -> 1 | D2: =NMRPrep[[#This Row],['#]] -> 0 | E2: 46097 | F2: 2 | G2: =IFERROR(IF(NMRPrep[[#This Row],[Sample (uL) ]]=0, (NMRResults[[#This Row],[IS Protons]]/NMRResults[[#This Row],[NH4 Protons]])*(NMRResults[[#This Row],[NH4 Peak Area]]/NMRResults[[#This Row],[IS Area]])*NMRResults[[#This Row],[IS Concentration (mM)]]*(NMRPrep[[#This Row],[Total (uL) ]]/SUM(NMRPrep[[#This Row],[DI (uL) ]:[ NH4Cl (uL)]])), IFERROR((NMRResults[[#This Row],[IS Protons]]/NMRResults[[#This Row],[NH4 Protons]])*(NMRResults[[#This Row],[NH4 Peak Area]]/NMRResults[[#This Row],[IS Area]])*NMRResults[[#This Row],[IS Concentration (mM)]]*(NMRPrep[[#This Row],[Total (uL) ]]/NMRPrep[[#This Row],[Sample (uL) ]]),0)), ) -> 0.73529412 | H2: =IF(ISBLANK(NMRPrep[[#This Row],[Total (uL) ]]), 0, NMRPrep[[#This Row],[1mM Maleic Acid (uL) ]]/NMRPrep[[#This Row],[Total (uL) ]]) -> 0.077279753 | I2: =2 -> 2 | J2: =4 -> 4 | K2: =1 -> 1
A3: =Sampling!D3 -> 46094 | B3: {=IF(ISBLANK(INDEX(SampleList[NMR],ROW()-1)),"Not Requested",INDEX(SampleList[Experiment ID],ROW()-1))} -> HPHT_070 | C3: =SampleList[[#This Row],[Duration (Days)]] -> 60 | D3: =NMRPrep[[#This Row],['#]] -> 0 | E3: 46097 | F3: 1.12 | G3: =IFERROR(IF(NMRPrep[[#This Row],[Sample (uL) ]]=0, (NMRResults[[#This Row],[IS Protons]]/NMRResults[[#This Row],[NH4 Protons]])*(NMRResults[[#This Row],[NH4 Peak Area]]/NMRResults[[#This Row],[IS Area]])*NMRResults[[#This Row],[IS Concentration (mM)]]*(NMRPrep[[#This Row],[Total (uL) ]]/SUM(NMRPrep[[#This Row],[DI (uL) ]:[ NH4Cl (uL)]])), IFERROR((NMRResults[[#This Row],[IS Protons]]/NMRResults[[#This Row],[NH4 Protons]])*(NMRResults[[#This Row],[NH4 Peak Area]]/NMRResults[[#This Row],[IS Area]])*NMRResults[[#This Row],[IS Concentration (mM)]]*(NMRPrep[[#This Row],[Total (uL) ]]/NMRPrep[[#This Row],[Sample (uL) ]]),0)), ) -> 0.41176471 | H3: =IF(ISBLANK(NMRPrep[[#This Row],[Total (uL) ]]), 0, NMRPrep[[#This Row],[1mM Maleic Acid (uL) ]]/NMRPrep[[#This Row],[Total (uL) ]]) -> 0.077279753 | I3: =2 -> 2 | J3: =4 -> 4 | K3: =1 -> 1
A4: =Sampling!D4 -> 46094 | B4: {=IF(ISBLANK(INDEX(SampleList[NMR],ROW()-1)),"Not Requested",INDEX(SampleList[Experiment ID],ROW()-1))} -> HPHT_089 | C4: =SampleList[[#This Row],[Duration (Days)]] -> 0 | D4: =NMRPrep[[#This Row],['#]] -> 0 | E4: 46097 | F4: 0.25 | G4: =IFERROR(IF(NMRPrep[[#This Row],[Sample (uL) ]]=0, (NMRResults[[#This Row],[IS Protons]]/NMRResults[[#This Row],[NH4 Protons]])*(NMRResults[[#This Row],[NH4 Peak Area]]/NMRResults[[#This Row],[IS Area]])*NMRResults[[#This Row],[IS Concentration (mM)]]*(NMRPrep[[#This Row],[Total (uL) ]]/SUM(NMRPrep[[#This Row],[DI (uL) ]:[ NH4Cl (uL)]])), IFERROR((NMRResults[[#This Row],[IS Protons]]/NMRResults[[#This Row],[NH4 Protons]])*(NMRResults[[#This Row],[NH4 Peak Area]]/NMRResults[[#This Row],[IS Area]])*NMRResults[[#This Row],[IS Concentration (mM)]]*(NMRPrep[[#This Row],[Total (uL) ]]/NMRPrep[[#This Row],[Sample (uL) ]]),0)), ) -> 0.091911765 | H4: =IF(ISBLANK(NMRPrep[[#This Row],[Total (uL) ]]), 0, NMRPrep[[#This Row],[1mM Maleic Acid (uL) ]]/NMRPrep[[#This Row],[Total (uL) ]]) -> 0.077279753 | I4: =2 -> 2 | J4: =4 -> 4 | K4: =1 -> 1
A5: =Sampling!D5 -> 46094 | B5: {=IF(ISBLANK(INDEX(SampleList[NMR],ROW()-1)),"Not Requested",INDEX(SampleList[Experiment ID],ROW()-1))} -> NH4-Teflon | C5: =SampleList[[#This Row],[Duration (Days)]] -> 0 | D5: =NMRPrep[[#This Row],['#]] -> 0 | E5: 46097 | F5: 3.22 | G5: =IFERROR(IF(NMRPrep[[#This Row],[Sample (uL) ]]=0, (NMRResults[[#This Row],[IS Protons]]/NMRResults[[#This Row],[NH4 Protons]])*(NMRResults[[#This Row],[NH4 Peak Area]]/NMRResults[[#This Row],[IS Area]])*NMRResults[[#This Row],[IS Concentration (mM)]]*(NMRPrep[[#This Row],[Total (uL) ]]/SUM(NMRPrep[[#This Row],[DI (uL) ]:[ NH4Cl (uL)]])), IFERROR((NMRResults[[#This Row],[IS Protons]]/NMRResults[[#This Row],[NH4 Protons]])*(NMRResults[[#This Row],[NH4 Peak Area]]/NMRResults[[#This Row],[IS Area]])*NMRResults[[#This Row],[IS Concentration (mM)]]*(NMRPrep[[#This Row],[Total (uL) ]]/NMRPrep[[#This Row],[Sample (uL) ]]),0)), ) -> 1.1838235 | H5: =IF(ISBLANK(NMRPrep[[#This Row],[Total (uL) ]]), 0, NMRPrep[[#This Row],[1mM Maleic Acid (uL) ]]/NMRPrep[[#This Row],[Total (uL) ]]) -> 0.077279753 | I5: =2 -> 2 | J5: =4 -> 4 | K5: =1 -> 1
A6: =Sampling!D6 -> 46097 | B6: {=IF(ISBLANK(INDEX(SampleList[NMR],ROW()-1)),"Not Requested",INDEX(SampleList[Experiment ID],ROW()-1))} -> NH4-Teflon | C6: =SampleList[[#This Row],[Duration (Days)]] -> 3 | D6: =NMRPrep[[#This Row],['#]] -> 0 | E6: 46097 | F6: 3.05 | G6: =IFERROR(IF(NMRPrep[[#This Row],[Sample (uL) ]]=0, (NMRResults[[#This Row],[IS Protons]]/NMRResults[[#This Row],[NH4 Protons]])*(NMRResults[[#This Row],[NH4 Peak Area]]/NMRResults[[#This Row],[IS Area]])*NMRResults[[#This Row],[IS Concentration (mM)]]*(NMRPrep[[#This Row],[Total (uL) ]]/SUM(NMRPrep[[#This Row],[DI (uL) ]:[ NH4Cl (uL)]])), IFERROR((NMRResults[[#This Row],[IS Protons]]/NMRResults[[#This Row],[NH4 Protons]])*(NMRResults[[#This Row],[NH4 Peak Area]]/NMRResults[[#This Row],[IS Area]])*NMRResults[[#This Row],[IS Concentration (mM)]]*(NMRPrep[[#This Row],[Total (uL) ]]/NMRPrep[[#This Row],[Sample (uL) ]]),0)), ) -> 1.1213235 | H6: =IF(ISBLANK(NMRPrep[[#This Row],[Total (uL) ]]), 0, NMRPrep[[#This Row],[1mM Maleic Acid (uL) ]]/NMRPrep[[#This Row],[Total (uL) ]]) -> 0.077279753 | I6: =2 -> 2 | J6: =4 -> 4 | K6: =1 -> 1
A7: =Sampling!D7 -> 46094 | B7: {=IF(ISBLANK(INDEX(SampleList[NMR],ROW()-1)),"Not Requested",INDEX(SampleList[Experiment ID],ROW()-1))} -> HPHT_070_Desorption | C7: =SampleList[[#This Row],[Duration (Days)]] -> 0 | D7: =NMRPrep[[#This Row],['#]] -> 0 | E7: 46097 | F7: 0.13 | G7: =IFERROR(IF(NMRPrep[[#This Row],[Sample (uL) ]]=0, (NMRResults[[#This Row],[IS Protons]]/NMRResults[[#This Row],[NH4 Protons]])*(NMRResults[[#This Row],[NH4 Peak Area]]/NMRResults[[#This Row],[IS Area]])*NMRResults[[#This Row],[IS Concentration (mM)]]*(NMRPrep[[#This Row],[Total (uL) ]]/SUM(NMRPrep[[#This Row],[DI (uL) ]:[ NH4Cl (uL)]])), IFERROR((NMRResults[[#This Row],[IS Protons]]/NMRResults[[#This Row],[NH4 Protons]])*(NMRResults[[#This Row],[NH4 Peak Area]]/NMRResults[[#This Row],[IS Area]])*NMRResults[[#This Row],[IS Concentration (mM)]]*(NMRPrep[[#This Row],[Total (uL) ]]/NMRPrep[[#This Row],[Sample (uL) ]]),0)), ) -> 0.047794118 | H7: =IF(ISBLANK(NMRPrep[[#This Row],[Total (uL) ]]), 0, NMRPrep[[#This Row],[1mM Maleic Acid (uL) ]]/NMRPrep[[#This Row],[Total (uL) ]]) -> 0.077279753 | I7: =2 -> 2 | J7: =4 -> 4 | K7: =1 -> 1
A8: =Sampling!D8 -> 46097 | B8: {=IF(ISBLANK(INDEX(SampleList[NMR],ROW()-1)),"Not Requested",INDEX(SampleList[Experiment ID],ROW()-1))} -> HPHT_101 | C8: =SampleList[[#This Row],[Duration (Days)]] -> 3 | D8: =NMRPrep[[#This Row],['#]] -> 0 | E8: 46097 | F8: 0.15 | G8: =IFERROR(IF(NMRPrep[[#This Row],[Sample (uL) ]]=0, (NMRResults[[#This Row],[IS Protons]]/NMRResults[[#This Row],[NH4 Protons]])*(NMRResults[[#This Row],[NH4 Peak Area]]/NMRResults[[#This Row],[IS Area]])*NMRResults[[#This Row],[IS Concentration (mM)]]*(NMRPrep[[#This Row],[Total (uL) ]]/SUM(NMRPrep[[#This Row],[DI (uL) ]:[ NH4Cl (uL)]])), IFERROR((NMRResults[[#This Row],[IS Protons]]/NMRResults[[#This Row],[NH4 Protons]])*(NMRResults[[#This Row],[NH4 Peak Area]]/NMRResults[[#This Row],[IS Area]])*NMRResults[[#This Row],[IS Concentration (mM)]]*(NMRPrep[[#This Row],[Total (uL) ]]/NMRPrep[[#This Row],[Sample (uL) ]]),0)), ) -> 0.055147059 | H8: =IF(ISBLANK(NMRPrep[[#This Row],[Total (uL) ]]), 0, NMRPrep[[#This Row],[1mM Maleic Acid (uL) ]]/NMRPrep[[#This Row],[Total (uL) ]]) -> 0.077279753 | I8: =2 -> 2 | J8: =4 -> 4 | K8: =1 -> 1
A9: =Sampling!D9 -> 46097 | B9: {=IF(ISBLANK(INDEX(SampleList[NMR],ROW()-1)),"Not Requested",INDEX(SampleList[Experiment ID],ROW()-1))} -> HPHT_102 | C9: =SampleList[[#This Row],[Duration (Days)]] -> 3 | D9: =NMRPrep[[#This Row],['#]] -> 0 | E9: 46097 | F9: 0.13 | G9: =IFERROR(IF(NMRPrep[[#This Row],[Sample (uL) ]]=0, (NMRResults[[#This Row],[IS Protons]]/NMRResults[[#This Row],[NH4 Protons]])*(NMRResults[[#This Row],[NH4 Peak Area]]/NMRResults[[#This Row],[IS Area]])*NMRResults[[#This Row],[IS Concentration (mM)]]*(NMRPrep[[#This Row],[Total (uL) ]]/SUM(NMRPrep[[#This Row],[DI (uL) ]:[ NH4Cl (uL)]])), IFERROR((NMRResults[[#This Row],[IS Protons]]/NMRResults[[#This Row],[NH4 Protons]])*(NMRResults[[#This Row],[NH4 Peak Area]]/NMRResults[[#This Row],[IS Area]])*NMRResults[[#This Row],[IS Concentration (mM)]]*(NMRPrep[[#This Row],[Total (uL) ]]/NMRPrep[[#This Row],[Sample (uL) ]]),0)), ) -> 0.047794118 | H9: =IF(ISBLANK(NMRPrep[[#This Row],[Total (uL) ]]), 0, NMRPrep[[#This Row],[1mM Maleic Acid (uL) ]]/NMRPrep[[#This Row],[Total (uL) ]]) -> 0.077279753 | I9: =2 -> 2 | J9: =4 -> 4 | K9: =1 -> 1
A10: =Sampling!D10 -> 46097 | B10: {=IF(ISBLANK(INDEX(SampleList[NMR],ROW()-1)),"Not Requested",INDEX(SampleList[Experiment ID],ROW()-1))} -> HPHT_095_Desorption | C10: =SampleList[[#This Row],[Duration (Days)]] -> 3 | D10: =NMRPrep[[#This Row],['#]] -> 0 | E10: 46097 | F10: 0.23 | G10: =IFERROR(IF(NMRPrep[[#This Row],[Sample (uL) ]]=0, (NMRResults[[#This Row],[IS Protons]]/NMRResults[[#This Row],[NH4 Protons]])*(NMRResults[[#This Row],[NH4 Peak Area]]/NMRResults[[#This Row],[IS Area]])*NMRResults[[#This Row],[IS Concentration (mM)]]*(NMRPrep[[#This Row],[Total (uL) ]]/SUM(NMRPrep[[#This Row],[DI (uL) ]:[ NH4Cl (uL)]])), IFERROR((NMRResults[[#This Row],[IS Protons]]/NMRResults[[#This Row],[NH4 Protons]])*(NMRResults[[#This Row],[NH4 Peak Area]]/NMRResults[[#This Row],[IS Area]])*NMRResults[[#This Row],[IS Concentration (mM)]]*(NMRPrep[[#This Row],[Total (uL) ]]/NMRPrep[[#This Row],[Sample (uL) ]]),0)), ) -> 0.084558824 | H10: =IF(ISBLANK(NMRPrep[[#This Row],[Total (uL) ]]), 0, NMRPrep[[#This Row],[1mM Maleic Acid (uL) ]]/NMRPrep[[#This Row],[Total (uL) ]]) -> 0.077279753 | I10: =2 -> 2 | J10: =4 -> 4 | K10: =1 -> 1
A11: =Sampling!D11 -> 46097 | B11: {=IF(ISBLANK(INDEX(SampleList[NMR],ROW()-1)),"Not Requested",INDEX(SampleList[Experiment ID],ROW()-1))} -> HPHT_097 | C11: =SampleList[[#This Row],[Duration (Days)]] -> 4 | D11: =NMRPrep[[#This Row],['#]] -> 0 | E11: 46097 | F11: 2.41 | G11: =IFERROR(IF(NMRPrep[[#This Row],[Sample (uL) ]]=0, (NMRResults[[#This Row],[IS Protons]]/NMRResults[[#This Row],[NH4 Protons]])*(NMRResults[[#This Row],[NH4 Peak Area]]/NMRResults[[#This Row],[IS Area]])*NMRResults[[#This Row],[IS Concentration (mM)]]*(NMRPrep[[#This Row],[Total (uL) ]]/SUM(NMRPrep[[#This Row],[DI (uL) ]:[ NH4Cl (uL)]])), IFERROR((NMRResults[[#This Row],[IS Protons]]/NMRResults[[#This Row],[NH4 Protons]])*(NMRResults[[#This Row],[NH4 Peak Area]]/NMRResults[[#This Row],[IS Area]])*NMRResults[[#This Row],[IS Concentration (mM)]]*(NMRPrep[[#This Row],[Total (uL) ]]/NMRPrep[[#This Row],[Sample (uL) ]]),0)), ) -> 0.88602941 | H11: =IF(ISBLANK(NMRPrep[[#This Row],[Total (uL) ]]), 0, NMRPrep[[#This Row],[1mM Maleic Acid (uL) ]]/NMRPrep[[#This Row],[Total (uL) ]]) -> 0.077279753 | I11: =2 -> 2 | J11: =4 -> 4 | K11: =1 -> 1
A12: =Sampling!D12 -> 46097 | B12: {=IF(ISBLANK(INDEX(SampleList[NMR],ROW()-1)),"Not Requested",INDEX(SampleList[Experiment ID],ROW()-1))} -> Standard | C12: =SampleList[[#This Row],[Duration (Days)]] -> 0 | D12: =NMRPrep[[#This Row],['#]] -> 0 | E12: 46097 | F12: 6.76 | G12: =IFERROR(IF(NMRPrep[[#This Row],[Sample (uL) ]]=0, (NMRResults[[#This Row],[IS Protons]]/NMRResults[[#This Row],[NH4 Protons]])*(NMRResults[[#This Row],[NH4 Peak Area]]/NMRResults[[#This Row],[IS Area]])*NMRResults[[#This Row],[IS Concentration (mM)]]*(NMRPrep[[#This Row],[Total (uL) ]]/SUM(NMRPrep[[#This Row],[DI (uL) ]:[ NH4Cl (uL)]])), IFERROR((NMRResults[[#This Row],[IS Protons]]/NMRResults[[#This Row],[NH4 Protons]])*(NMRResults[[#This Row],[NH4 Peak Area]]/NMRResults[[#This Row],[IS Area]])*NMRResults[[#This Row],[IS Concentration (mM)]]*(NMRPrep[[#This Row],[Total (uL) ]]/NMRPrep[[#This Row],[Sample (uL) ]]),0)), ) -> 0.38148984 | H12: =IF(ISBLANK(NMRPrep[[#This Row],[Total (uL) ]]), 0, NMRPrep[[#This Row],[1mM Maleic Acid (uL) ]]/NMRPrep[[#This Row],[Total (uL) ]]) -> 0.077279753 | I12: =2 -> 2 | J12: =4 -> 4 | K12: =1 -> 1
A13: =Sampling!D13 -> 46097 | B13: {=IF(ISBLANK(INDEX(SampleList[NMR],ROW()-1)),"Not Requested",INDEX(SampleList[Experiment ID],ROW()-1))} -> HPHT_096 | C13: =SampleList[[#This Row],[Duration (Days)]] -> 10 | D13: =NMRPrep[[#This Row],['#]] -> 0 | E13: 46097 | G13: =IFERROR(IF(NMRPrep[[#This Row],[Sample (uL) ]]=0, (NMRResults[[#This Row],[IS Protons]]/NMRResults[[#This Row],[NH4 Protons]])*(NMRResults[[#This Row],[NH4 Peak Area]]/NMRResults[[#This Row],[IS Area]])*NMRResults[[#This Row],[IS Concentration (mM)]]*(NMRPrep[[#This Row],[Total (uL) ]]/SUM(NMRPrep[[#This Row],[DI (uL) ]:[ NH4Cl (uL)]])), IFERROR((NMRResults[[#This Row],[IS Protons]]/NMRResults[[#This Row],[NH4 Protons]])*(NMRResults[[#This Row],[NH4 Peak Area]]/NMRResults[[#This Row],[IS Area]])*NMRResults[[#This Row],[IS Concentration (mM)]]*(NMRPrep[[#This Row],[Total (uL) ]]/NMRPrep[[#This Row],[Sample (uL) ]]),0)), ) -> 0 | H13: =IF(ISBLANK(NMRPrep[[#This Row],[Total (uL) ]]), 0, NMRPrep[[#This Row],[1mM Maleic Acid (uL) ]]/NMRPrep[[#This Row],[Total (uL) ]]) -> 0.077279753 | I13: =2 -> 2 | J13: =4 -> 4 | K13: =1 -> 1
A14: =Sampling!D14 -> 46097 | B14: {=IF(ISBLANK(INDEX(SampleList[NMR],ROW()-1)),"Not Requested",INDEX(SampleList[Experiment ID],ROW()-1))} -> HPHT_079 | C14: =SampleList[[#This Row],[Duration (Days)]] -> 39 | D14: =NMRPrep[[#This Row],['#]] -> 0 | E14: 46099 | F14: 0.25 | G14: =IFERROR(IF(NMRPrep[[#This Row],[Sample (uL) ]]=0, (NMRResults[[#This Row],[IS Protons]]/NMRResults[[#This Row],[NH4 Protons]])*(NMRResults[[#This Row],[NH4 Peak Area]]/NMRResults[[#This Row],[IS Area]])*NMRResults[[#This Row],[IS Concentration (mM)]]*(NMRPrep[[#This Row],[Total (uL) ]]/SUM(NMRPrep[[#This Row],[DI (uL) ]:[ NH4Cl (uL)]])), IFERROR((NMRResults[[#This Row],[IS Protons]]/NMRResults[[#This Row],[NH4 Protons]])*(NMRResults[[#This Row],[NH4 Peak Area]]/NMRResults[[#This Row],[IS Area]])*NMRResults[[#This Row],[IS Concentration (mM)]]*(NMRPrep[[#This Row],[Total (uL) ]]/NMRPrep[[#This Row],[Sample (uL) ]]),0)), ) -> 0.091911765 | H14: =IF(ISBLANK(NMRPrep[[#This Row],[Total (uL) ]]), 0, NMRPrep[[#This Row],[1mM Maleic Acid (uL) ]]/NMRPrep[[#This Row],[Total (uL) ]]) -> 0.077279753 | I14: =2 -> 2 | J14: =4 -> 4 | K14: =1 -> 1
A15: =Sampling!D15 -> 46099 | B15: {=IF(ISBLANK(INDEX(SampleList[NMR],ROW()-1)),"Not Requested",INDEX(SampleList[Experiment ID],ROW()-1))} -> HPHT_097 | C15: =SampleList[[#This Row],[Duration (Days)]] -> 6 | D15: =NMRPrep[[#This Row],['#]] -> 0 | E15: 46099 | F15: 2.13 | G15: =IFERROR(IF(NMRPrep[[#This Row],[Sample (uL) ]]=0, (NMRResults[[#This Row],[IS Protons]]/NMRResults[[#This Row],[NH4 Protons]])*(NMRResults[[#This Row],[NH4 Peak Area]]/NMRResults[[#This Row],[IS Area]])*NMRResults[[#This Row],[IS Concentration (mM)]]*(NMRPrep[[#This Row],[Total (uL) ]]/SUM(NMRPrep[[#This Row],[DI (uL) ]:[ NH4Cl (uL)]])), IFERROR((NMRResults[[#This Row],[IS Protons]]/NMRResults[[#This Row],[NH4 Protons]])*(NMRResults[[#This Row],[NH4 Peak Area]]/NMRResults[[#This Row],[IS Area]])*NMRResults[[#This Row],[IS Concentration (mM)]]*(NMRPrep[[#This Row],[Total (uL) ]]/NMRPrep[[#This Row],[Sample (uL) ]]),0)), ) -> 0.78308824 | H15: =IF(ISBLANK(NMRPrep[[#This Row],[Total (uL) ]]), 0, NMRPrep[[#This Row],[1mM Maleic Acid (uL) ]]/NMRPrep[[#This Row],[Total (uL) ]]) -> 0.077279753 | I15: =2 -> 2 | J15: =4 -> 4 | K15: =1 -> 1
A16: =Sampling!D16 -> 46080 | B16: {=IF(ISBLANK(INDEX(SampleList[NMR],ROW()-1)),"Not Requested",INDEX(SampleList[Experiment ID],ROW()-1))} -> Not Requested | C16: =Sampling!E16 -> 6 | D16: =NMRPrep[[#This Row],['#]] -> 0 | G16: =IFERROR(IF(NMRPrep[[#This Row],[Sample (uL) ]]=0, (NMRResults[[#This Row],[IS Protons]]/NMRResults[[#This Row],[NH4 Protons]])*(NMRResults[[#This Row],[NH4 Peak Area]]/NMRResults[[#This Row],[IS Area]])*NMRResults[[#This Row],[IS Concentration (mM)]]*(NMRPrep[[#This Row],[Total (uL) ]]/SUM(NMRPrep[[#This Row],[DI (uL) ]:[ NH4Cl (uL)]])), IFERROR((NMRResults[[#This Row],[IS Protons]]/NMRResults[[#This Row],[NH4 Protons]])*(NMRResults[[#This Row],[NH4 Peak Area]]/NMRResults[[#This Row],[IS Area]])*NMRResults[[#This Row],[IS Concentration (mM)]]*(NMRPrep[[#This Row],[Total (uL) ]]/NMRPrep[[#This Row],[Sample (uL) ]]),0)), ) -> 0 | H16: =IF(ISBLANK(NMRPrep[[#This Row],[Total (uL) ]]), 0, NMRPrep[[#This Row],[1mM Maleic Acid (uL) ]]/NMRPrep[[#This Row],[Total (uL) ]]) -> 0.077279753 | I16: =2 -> 2 | J16: =4 -> 4 | K16: =1 -> 1
A17: =Sampling!D17 -> 46080 | B17: {=IF(ISBLANK(INDEX(SampleList[NMR],ROW()-1)),"Not Requested",INDEX(SampleList[Experiment ID],ROW()-1))} -> Not Requested | C17: =Sampling!E17 -> 46 | D17: =NMRPrep[[#This Row],['#]] -> 0 | G17: =IFERROR(IF(NMRPrep[[#This Row],[Sample (uL) ]]=0, (NMRResults[[#This Row],[IS Protons]]/NMRResults[[#This Row],[NH4 Protons]])*(NMRResults[[#This Row],[NH4 Peak Area]]/NMRResults[[#This Row],[IS Area]])*NMRResults[[#This Row],[IS Concentration (mM)]]*(NMRPrep[[#This Row],[Total (uL) ]]/SUM(NMRPrep[[#This Row],[DI (uL) ]:[ NH4Cl (uL)]])), IFERROR((NMRResults[[#This Row],[IS Protons]]/NMRResults[[#This Row],[NH4 Protons]])*(NMRResults[[#This Row],[NH4 Peak Area]]/NMRResults[[#This Row],[IS Area]])*NMRResults[[#This Row],[IS Concentration (mM)]]*(NMRPrep[[#This Row],[Total (uL) ]]/NMRPrep[[#This Row],[Sample (uL) ]]),0)), ) -> 0 | H17: =IF(ISBLANK(NMRPrep[[#This Row],[Total (uL) ]]), 0, NMRPrep[[#This Row],[1mM Maleic Acid (uL) ]]/NMRPrep[[#This Row],[Total (uL) ]]) -> 0.077279753 | I17: =2 -> 2 | J17: =4 -> 4 | K17: =1 -> 1
A18: =Sampling!D18 -> 46080 | B18: {=IF(ISBLANK(INDEX(SampleList[NMR],ROW()-1)),"Not Requested",INDEX(SampleList[Experiment ID],ROW()-1))} -> Not Requested | C18: =Sampling!E18 -> 18 | D18: =NMRPrep[[#This Row],['#]] -> 0 | G18: =IFERROR(IF(NMRPrep[[#This Row],[Sample (uL) ]]=0, (NMRResults[[#This Row],[IS Protons]]/NMRResults[[#This Row],[NH4 Protons]])*(NMRResults[[#This Row],[NH4 Peak Area]]/NMRResults[[#This Row],[IS Area]])*NMRResults[[#This Row],[IS Concentration (mM)]]*(NMRPrep[[#This Row],[Total (uL) ]]/SUM(NMRPrep[[#This Row],[DI (uL) ]:[ NH4Cl (uL)]])), IFERROR((NMRResults[[#This Row],[IS Protons]]/NMRResults[[#This Row],[NH4 Protons]])*(NMRResults[[#This Row],[NH4 Peak Area]]/NMRResults[[#This Row],[IS Area]])*NMRResults[[#This Row],[IS Concentration (mM)]]*(NMRPrep[[#This Row],[Total (uL) ]]/NMRPrep[[#This Row],[Sample (uL) ]]),0)), ) -> 0 | H18: =IF(ISBLANK(NMRPrep[[#This Row],[Total (uL) ]]), 0, NMRPrep[[#This Row],[1mM Maleic Acid (uL) ]]/NMRPrep[[#This Row],[Total (uL) ]]) -> 0.077279753 | I18: =2 -> 2 | J18: =4 -> 4 | K18: =1 -> 1
A19: =Sampling!D19 -> 46080 | B19: {=IF(ISBLANK(INDEX(SampleList[NMR],ROW()-1)),"Not Requested",INDEX(SampleList[Experiment ID],ROW()-1))} -> Not Requested | C19: =Sampling!E19 -> 22 | D19: =NMRPrep[[#This Row],['#]] -> 0 | G19: =IFERROR(IF(NMRPrep[[#This Row],[Sample (uL) ]]=0, (NMRResults[[#This Row],[IS Protons]]/NMRResults[[#This Row],[NH4 Protons]])*(NMRResults[[#This Row],[NH4 Peak Area]]/NMRResults[[#This Row],[IS Area]])*NMRResults[[#This Row],[IS Concentration (mM)]]*(NMRPrep[[#This Row],[Total (uL) ]]/SUM(NMRPrep[[#This Row],[DI (uL) ]:[ NH4Cl (uL)]])), IFERROR((NMRResults[[#This Row],[IS Protons]]/NMRResults[[#This Row],[NH4 Protons]])*(NMRResults[[#This Row],[NH4 Peak Area]]/NMRResults[[#This Row],[IS Area]])*NMRResults[[#This Row],[IS Concentration (mM)]]*(NMRPrep[[#This Row],[Total (uL) ]]/NMRPrep[[#This Row],[Sample (uL) ]]),0)), ) -> 0 | H19: =IF(ISBLANK(NMRPrep[[#This Row],[Total (uL) ]]), 0, NMRPrep[[#This Row],[1mM Maleic Acid (uL) ]]/NMRPrep[[#This Row],[Total (uL) ]]) -> 0.077279753 | I19: =2 -> 2 | J19: =4 -> 4 | K19: =1 -> 1
A20: =Sampling!D20 -> 46083 | B20: {=IF(ISBLANK(INDEX(SampleList[NMR],ROW()-1)),"Not Requested",INDEX(SampleList[Experiment ID],ROW()-1))} -> Not Requested | C20: =Sampling!E20 -> 20 | D20: =NMRPrep[[#This Row],['#]] -> 0 | G20: =IFERROR(IF(NMRPrep[[#This Row],[Sample (uL) ]]=0, (NMRResults[[#This Row],[IS Protons]]/NMRResults[[#This Row],[NH4 Protons]])*(NMRResults[[#This Row],[NH4 Peak Area]]/NMRResults[[#This Row],[IS Area]])*NMRResults[[#This Row],[IS Concentration (mM)]]*(NMRPrep[[#This Row],[Total (uL) ]]/SUM(NMRPrep[[#This Row],[DI (uL) ]:[ NH4Cl (uL)]])), IFERROR((NMRResults[[#This Row],[IS Protons]]/NMRResults[[#This Row],[NH4 Protons]])*(NMRResults[[#This Row],[NH4 Peak Area]]/NMRResults[[#This Row],[IS Area]])*NMRResults[[#This Row],[IS Concentration (mM)]]*(NMRPrep[[#This Row],[Total (uL) ]]/NMRPrep[[#This Row],[Sample (uL) ]]),0)), ) -> 0 | H20: =IF(ISBLANK(NMRPrep[[#This Row],[Total (uL) ]]), 0, NMRPrep[[#This Row],[1mM Maleic Acid (uL) ]]/NMRPrep[[#This Row],[Total (uL) ]]) -> 0.077279753 | I20: =2 -> 2 | J20: =4 -> 4 | K20: =1 -> 1
A21: =Sampling!D21 -> 46083 | B21: {=IF(ISBLANK(INDEX(SampleList[NMR],ROW()-1)),"Not Requested",INDEX(SampleList[Experiment ID],ROW()-1))} -> Not Requested | C21: =Sampling!E21 -> 8 | D21: =NMRPrep[[#This Row],['#]] -> 0 | G21: =IFERROR(IF(NMRPrep[[#This Row],[Sample (uL) ]]=0, (NMRResults[[#This Row],[IS Protons]]/NMRResults[[#This Row],[NH4 Protons]])*(NMRResults[[#This Row],[NH4 Peak Area]]/NMRResults[[#This Row],[IS Area]])*NMRResults[[#This Row],[IS Concentration (mM)]]*(NMRPrep[[#This Row],[Total (uL) ]]/SUM(NMRPrep[[#This Row],[DI (uL) ]:[ NH4Cl (uL)]])), IFERROR((NMRResults[[#This Row],[IS Protons]]/NMRResults[[#This Row],[NH4 Protons]])*(NMRResults[[#This Row],[NH4 Peak Area]]/NMRResults[[#This Row],[IS Area]])*NMRResults[[#This Row],[IS Concentration (mM)]]*(NMRPrep[[#This Row],[Total (uL) ]]/NMRPrep[[#This Row],[Sample (uL) ]]),0)), ) -> 0 | H21: =IF(ISBLANK(NMRPrep[[#This Row],[Total (uL) ]]), 0, NMRPrep[[#This Row],[1mM Maleic Acid (uL) ]]/NMRPrep[[#This Row],[Total (uL) ]]) -> 0.077279753 | I21: =2 -> 2 | J21: =4 -> 4 | K21: =1 -> 1
A22: =Sampling!D22 -> 46083 | B22: {=IF(ISBLANK(INDEX(SampleList[NMR],ROW()-1)),"Not Requested",INDEX(SampleList[Experiment ID],ROW()-1))} -> Not Requested | C22: =Sampling!E22 -> 10 | D22: =NMRPrep[[#This Row],['#]] -> 0 | G22: =IFERROR(IF(NMRPrep[[#This Row],[Sample (uL) ]]=0, (NMRResults[[#This Row],[IS Protons]]/NMRResults[[#This Row],[NH4 Protons]])*(NMRResults[[#This Row],[NH4 Peak Area]]/NMRResults[[#This Row],[IS Area]])*NMRResults[[#This Row],[IS Concentration (mM)]]*(NMRPrep[[#This Row],[Total (uL) ]]/SUM(NMRPrep[[#This Row],[DI (uL) ]:[ NH4Cl (uL)]])), IFERROR((NMRResults[[#This Row],[IS Protons]]/NMRResults[[#This Row],[NH4 Protons]])*(NMRResults[[#This Row],[NH4 Peak Area]]/NMRResults[[#This Row],[IS Area]])*NMRResults[[#This Row],[IS Concentration (mM)]]*(NMRPrep[[#This Row],[Total (uL) ]]/NMRPrep[[#This Row],[Sample (uL) ]]),0)), ) -> 0 | H22: =IF(ISBLANK(NMRPrep[[#This Row],[Total (uL) ]]), 0, NMRPrep[[#This Row],[1mM Maleic Acid (uL) ]]/NMRPrep[[#This Row],[Total (uL) ]]) -> 0.077279753 | I22: =2 -> 2 | J22: =4 -> 4 | K22: =1 -> 1
A23: =Sampling!D23 -> 46083 | B23: {=IF(ISBLANK(INDEX(SampleList[NMR],ROW()-1)),"Not Requested",INDEX(SampleList[Experiment ID],ROW()-1))} -> Not Requested | C23: =Sampling!E23 -> 2 | D23: =NMRPrep[[#This Row],['#]] -> 0 | G23: =IFERROR(IF(NMRPrep[[#This Row],[Sample (uL) ]]=0, (NMRResults[[#This Row],[IS Protons]]/NMRResults[[#This Row],[NH4 Protons]])*(NMRResults[[#This Row],[NH4 Peak Area]]/NMRResults[[#This Row],[IS Area]])*NMRResults[[#This Row],[IS Concentration (mM)]]*(NMRPrep[[#This Row],[Total (uL) ]]/SUM(NMRPrep[[#This Row],[DI (uL) ]:[ NH4Cl (uL)]])), IFERROR((NMRResults[[#This Row],[IS Protons]]/NMRResults[[#This Row],[NH4 Protons]])*(NMRResults[[#This Row],[NH4 Peak Area]]/NMRResults[[#This Row],[IS Area]])*NMRResults[[#This Row],[IS Concentration (mM)]]*(NMRPrep[[#This Row],[Total (uL) ]]/NMRPrep[[#This Row],[Sample (uL) ]]),0)), ) -> 0 | H23: =IF(ISBLANK(NMRPrep[[#This Row],[Total (uL) ]]), 0, NMRPrep[[#This Row],[1mM Maleic Acid (uL) ]]/NMRPrep[[#This Row],[Total (uL) ]]) -> 0.077279753 | I23: =2 -> 2 | J23: =4 -> 4 | K23: =1 -> 1
A24: =Sampling!D24 -> 46086 | B24: {=IF(ISBLANK(INDEX(SampleList[NMR],ROW()-1)),"Not Requested",INDEX(SampleList[Experiment ID],ROW()-1))} -> Not Requested | C24: =Sampling!E24 -> 52 | D24: =NMRPrep[[#This Row],['#]] -> 0 | G24: =IFERROR(IF(NMRPrep[[#This Row],[Sample (uL) ]]=0, (NMRResults[[#This Row],[IS Protons]]/NMRResults[[#This Row],[NH4 Protons]])*(NMRResults[[#This Row],[NH4 Peak Area]]/NMRResults[[#This Row],[IS Area]])*NMRResults[[#This Row],[IS Concentration (mM)]]*(NMRPrep[[#This Row],[Total (uL) ]]/SUM(NMRPrep[[#This Row],[DI (uL) ]:[ NH4Cl (uL)]])), IFERROR((NMRResults[[#This Row],[IS Protons]]/NMRResults[[#This Row],[NH4 Protons]])*(NMRResults[[#This Row],[NH4 Peak Area]]/NMRResults[[#This Row],[IS Area]])*NMRResults[[#This Row],[IS Concentration (mM)]]*(NMRPrep[[#This Row],[Total (uL) ]]/NMRPrep[[#This Row],[Sample (uL) ]]),0)), ) -> 0 | H24: =IF(ISBLANK(NMRPrep[[#This Row],[Total (uL) ]]), 0, NMRPrep[[#This Row],[1mM Maleic Acid (uL) ]]/NMRPrep[[#This Row],[Total (uL) ]]) -> 0.077279753 | I24: =2 -> 2 | J24: =4 -> 4 | K24: =1 -> 1
A25: =Sampling!D25 -> 46086 | B25: {=IF(ISBLANK(INDEX(SampleList[NMR],ROW()-1)),"Not Requested",INDEX(SampleList[Experiment ID],ROW()-1))} -> Not Requested | C25: =Sampling!E25 -> 22 | D25: =NMRPrep[[#This Row],['#]] -> 0 | G25: =IFERROR(IF(NMRPrep[[#This Row],[Sample (uL) ]]=0, (NMRResults[[#This Row],[IS Protons]]/NMRResults[[#This Row],[NH4 Protons]])*(NMRResults[[#This Row],[NH4 Peak Area]]/NMRResults[[#This Row],[IS Area]])*NMRResults[[#This Row],[IS Concentration (mM)]]*(NMRPrep[[#This Row],[Total (uL) ]]/SUM(NMRPrep[[#This Row],[DI (uL) ]:[ NH4Cl (uL)]])), IFERROR((NMRResults[[#This Row],[IS Protons]]/NMRResults[[#This Row],[NH4 Protons]])*(NMRResults[[#This Row],[NH4 Peak Area]]/NMRResults[[#This Row],[IS Area]])*NMRResults[[#This Row],[IS Concentration (mM)]]*(NMRPrep[[#This Row],[Total (uL) ]]/NMRPrep[[#This Row],[Sample (uL) ]]),0)), ) -> 0 | H25: =IF(ISBLANK(NMRPrep[[#This Row],[Total (uL) ]]), 0, NMRPrep[[#This Row],[1mM Maleic Acid (uL) ]]/NMRPrep[[#This Row],[Total (uL) ]]) -> 0.077279753 | I25: =2 -> 2 | J25: =4 -> 4 | K25: =1 -> 1
A26: =Sampling!D26 -> 46086 | B26: {=IF(ISBLANK(INDEX(SampleList[NMR],ROW()-1)),"Not Requested",INDEX(SampleList[Experiment ID],ROW()-1))} -> Not Requested | C26: =Sampling!E26 -> 28 | D26: =NMRPrep[[#This Row],['#]] -> 0 | G26: =IFERROR(IF(NMRPrep[[#This Row],[Sample (uL) ]]=0, (NMRResults[[#This Row],[IS Protons]]/NMRResults[[#This Row],[NH4 Protons]])*(NMRResults[[#This Row],[NH4 Peak Area]]/NMRResults[[#This Row],[IS Area]])*NMRResults[[#This Row],[IS Concentration (mM)]]*(NMRPrep[[#This Row],[Total (uL) ]]/SUM(NMRPrep[[#This Row],[DI (uL) ]:[ NH4Cl (uL)]])), IFERROR((NMRResults[[#This Row],[IS Protons]]/NMRResults[[#This Row],[NH4 Protons]])*(NMRResults[[#This Row],[NH4 Peak Area]]/NMRResults[[#This Row],[IS Area]])*NMRResults[[#This Row],[IS Concentration (mM)]]*(NMRPrep[[#This Row],[Total (uL) ]]/NMRPrep[[#This Row],[Sample (uL) ]]),0)), ) -> 0 | H26: =IF(ISBLANK(NMRPrep[[#This Row],[Total (uL) ]]), 0, NMRPrep[[#This Row],[1mM Maleic Acid (uL) ]]/NMRPrep[[#This Row],[Total (uL) ]]) -> 0.077279753 | I26: =2 -> 2 | J26: =4 -> 4 | K26: =1 -> 1
